<?xml version="1.0" ?>

<robot name="iiwa">
    <link name="base_link">
        <visual>
            <geometry>
                <cylinder length="0.4" radius="0.2"/>
            </geometry>
            <origin rpy="0 0 0" xyz="0 0 0"/>
            <material name="grey">
                <color rgba="0.5 0.5 0.5 1"/>
            </material>
        </visual>
        <collision>
            <geometry>
                <cylinder length="0.4" radius="0.2"/>
            </geometry>
            <origin rpy="0 0 0" xyz="0 0 0"/>
        </collision>
    </link>

    
    <joint name="joint1" type="revolute">
        <parent link="base_link"/>
        <child link="link1"/>
        <origin xyz="0 0 0.2"/>
        <axis xyz="0 0 1" />
        <limit effort="320" velocity="1.48" lower="-2.97" upper="2.97"/>    </joint>
    
    
    <link name="link1">
        <visual>
            <geometry>
                <cylinder length="0.4" radius="0.1"/>
            </geometry>
            <origin rpy="0 0 0" xyz="0 0 0.2"/>
            <material name="blue">
                <color rgba="0 0 1 1"/>
            </material>
        </visual>
        <collision>
            <geometry>
                <cylinder length="0.4" radius="0.1"/>
            </geometry>
            <origin rpy="0 0 0" xyz="0 0 0.2"/>
        </collision>
        <inertial>
            <mass value="1"/>
            <inertia ixx="1.0" ixy="0.0" ixz="0.0" iyy="1.0" iyz="0.0" izz="1.0"/>
        </inertial>
    </link>
    

        <joint name="joint2" type="revolute">
        <parent link="link1"/>
        <child link="link2"/>
        <origin xyz="0 0.1 0.4"/>
        <axis xyz="0 1 0" />
        <limit effort="320" velocity="1.48" lower="-2.094" upper="2.094"/>
    </joint>

    
     <link name="link2">
        <visual>
            <geometry>
                <cylinder length="0.4" radius="0.1"/>
            </geometry>
            <origin rpy="0 0 0" xyz="0 0 0.2"/>
            <material name="red">
                <color rgba="1 0 0 1"/>
            </material>
        </visual>
        <collision>
            <geometry>
                <cylinder length="0.4" radius="0.1"/>
            </geometry>
            <origin rpy="0 0 0" xyz="0 0 0.2"/>
        </collision>
        <inertial>
            <mass value="1"/>
            <inertia ixx="1.0" ixy="0.0" ixz="0.0" iyy="1.0" iyz="0.0" izz="1.0"/>
        </inertial>
    </link>
    
          <joint name="joint3" type="revolute">
        <parent link="link2"/>
        <child link="link3"/>
        <origin xyz="0 0 0.4"/>
        <axis xyz="0 0 1" />
        <limit effort="176" velocity="1.74" lower="-2.97" upper="2.97"/>
    </joint>


    <link name="link3">
        <visual>
            <geometry>
                <cylinder length="0.4" radius="0.1"/>
            </geometry>
            <origin rpy="0 0 0" xyz="0 0 0.2"/>
            <material name="yellow">
                <color rgba="1 1 0 1"/>
            </material>
        </visual>
        <collision>
            <geometry>
                <cylinder length="0.4" radius="0.1"/>
            </geometry>
            <origin rpy="0 0 0" xyz="0 0 0.2"/>
        </collision>
        <inertial>
            <mass value="1"/>
            <inertia ixx="1.0" ixy="0.0" ixz="0.0" iyy="1.0" iyz="0.0" izz="1.0"/>
        </inertial>
    </link>



      <joint name="joint4" type="revolute">
        <parent link="link3"/>
        <child link="link4"/>
        <origin xyz="0 -0.1 0.4"/>
        <axis xyz="0 1 0" />
        <limit effort="176" velocity="1.3" lower="-2.094" upper="2.094"/>
    </joint>


    <link name="link4">
        <visual>
            <geometry>
                <cylinder length="0.4" radius="0.1"/>
            </geometry>
            <origin rpy="0 0 0" xyz="0 0 0.2"/>
            <material name="blue">
                <color rgba="0 0 1 1"/>
            </material>
        </visual>
        <collision>
            <geometry>
                <cylinder length="0.4" radius="0.1"/>
            </geometry>
            <origin rpy="0 0 0" xyz="0 0 0.2"/>
        </collision>
        <inertial>
            <mass value="1"/>
            <inertia ixx="1.0" ixy="0.0" ixz="0.0" iyy="1.0" iyz="0.0" izz="1.0"/>
        </inertial>
    </link>

      <joint name="joint5" type="revolute">
        <parent link="link4"/>
        <child link="link5"/>
        <origin xyz="0 0 0.4"/>
        <axis xyz="0 0 1" />
        <limit effort="110" velocity="2.26" lower="-2.97" upper="2.97"/>
    </joint>



    <link name="link5">
        <visual>
            <geometry>
                <cylinder length="0.4" radius="0.1"/>
            </geometry>
            <origin rpy="0 0 0" xyz="0 0 0.2"/>
            <material name="red">
                <color rgba="1 0 0 1"/>
            </material>
        </visual>
        <collision>
            <geometry>
                <cylinder length="0.4" radius="0.1"/>
            </geometry>
            <origin rpy="0 0 0" xyz="0 0 0.2"/>
        </collision>
        <inertial>
            <mass value="1"/>
            <inertia ixx="1.0" ixy="0.0" ixz="0.0" iyy="1.0" iyz="0.0" izz="1.0"/>
        </inertial>
    </link>


      <joint name="joint6" type="revolute">
        <parent link="link5"/>
        <child link="link6"/>
        <origin xyz="0 0.1 0.4"/>
        <axis xyz="0 1 0" />
        <limit effort="40" velocity="2.35" lower="-2.094" upper="2.094"/>
    </joint>

    <link name="link6">
        <visual>
            <geometry>
                <cylinder length="0.4" radius="0.1"/>
            </geometry>
            <origin rpy="0 0 0" xyz="0 0 0.2"/>
            <material name="yellow">
                <color rgba="1 1 0 1"/>
            </material>
        </visual>
        <collision>
            <geometry>
                <cylinder length="0.4" radius="0.1"/>
            </geometry>
            <origin rpy="0 0 0" xyz="0 0 0.2"/>
        </collision>
        <inertial>
            <mass value="1"/>
            <inertia ixx="1.0" ixy="0.0" ixz="0.0" iyy="1.0" iyz="0.0" izz="1.0"/>
        </inertial>
    </link>


      <joint name="joint7" type="revolute">
        <parent link="link6"/>
        <child link="end_effector"/>
        <origin xyz="0 0 0.4"/>
        <axis xyz="0 0 1" />
        <limit effort="40" velocity="2.35" lower="-3.14" upper="3.14"/>
    </joint>


    <link name="end_effector">
        <visual>
            <geometry>
                <cylinder length="0.05" radius="0.05"/>
            </geometry>
            <origin rpy="0 0 0" xyz="0 0 0.05"/>
            <material name="blue">
                <color rgba="0 0 1 1"/>
            </material>
        </visual>
        <collision>
            <geometry>
                <cylinder length="0.05" radius="0.05"/>
            </geometry>
            <origin rpy="0 0 0" xyz="0 0 0.05"/>
        </collision>
        <inertial>
            <mass value="1"/>
            <inertia ixx="1.0" ixy="0.0" ixz="0.0" iyy="1.0" iyz="0.0" izz="1.0"/>
        </inertial>
    </link>


</robot>
